Workbook

Sheet Návod
B1: NÁVOD – PLÁNOVÁNÍ, SCHVALOVÁNÍ A KONTROLA VIDEOOBSAHU
B3: K ČEMU SOUBOR SLOUŽÍ
C4: Jeden sdílený soubor pro dlouhodobou práci: každý měsíc se přidá nový natáčecí cyklus, scénáře se vkládají do společné databáze a Přehled se přepne na daný měsíc. Nic se nekopíruje, historie zůstává v témže souboru (filtrem podle měsíce nebo cyklu).
B5: LISTY
B6: Přehled | C6: Kontrolní panel pro vedení. Mění se jen dvě žluté buňky: vyhodnocovaný měsíc a natáčecí cyklus. Vše ostatní se počítá samo.
B7: Scénáře | C7: Hlavní databáze. Jeden řádek = jedno unikátní video nebo jeden díl série. Modré sloupce vyplňuje marketér, oranžové vedení, zelené výroba, šedé se počítají automaticky (nepřepisovat).
B8: Připomínky | C8: Každá připomínka Honzy / Radka = jeden řádek. Marketér doplní reakci, vedení nastaví stav (Nevyřešeno → Zapracováno → Uzavřeno). Připomínky zůstávají dohledatelné i po zapracování.
B9: Publikace | C9: Jeden řádek = jedno zveřejnění (profil × varianta). Z tohoto listu se bere datum první publikace a skutečný měsíc. Více zveřejnění jednoho videa (více profilů, hook A/B, repost) počet unikátních videí nezvyšuje.
B10: Série | C10: Jedna série = jeden řádek. Díly se evidují v listu Scénáře (sloupec ID série + Číslo dílu). Počty připravených, schválených, natočených a publikovaných dílů se dopočítají automaticky. Uzavření série je vědomé rozhodnutí: stav Uzavřená + kdo + kdy; sloupec „Lze uzavřít?“ hlídá podmínky.
B11: Nastavení | C11: Cíl videí za měsíc, poměry 30/40/20/10, 30/70 a 70/30, tolerance, natáčecí cykly (datum natáčení → termín schválení automaticky 7 dní předem), seznamy lidí a profilů.
B12: MĚSÍČNÍ POSTUP
B13: 1. Nastavení | C13: Do tabulky natáčecích cyklů doplňte datum natáčení (řádek pro daný měsíc už existuje). Termín schválení se dopočítá.
B14: 2. Marketéři | C14: Do listu Scénáře vloží každé téma: ID videa (např. V026), název, cyklus, plánovaný měsíc publikace, kategorii, typ zpracování, profil, charakter (u Honzy / Radka), cíl, myšlenku, scénář (text nebo odkaz na sdílený dokument), hooky, termín odevzdání a stav „K připomínkám“, jakmile je scénář hotový.
B15: 3. Vedení | C15: Honza / Radek otevřou scénář, připomínky píší do listu Připomínky. V listu Scénáře nastaví stav „K dopracování“, nebo „Schváleno“ + Schválil + Datum schválení. Bez jména a data se schválení hlásí jako chyba.
B16: 4. Před natáčením | C16: V Přehledu zkontrolujte sekce 4 a 5 (co chybí do mixu, kolik je po termínu). V listu Scénáře vyfiltrujte Stav schválení = Schváleno a daný cyklus – to je sada pro natáčecí den.
B17: 5. Po natáčení | C17: Výroba nastaví Stav výroby (Natočeno → Ve střihu → Sestříháno → Publikováno) a doplní odkazy. Každé zveřejnění zapíše do listu Publikace (profil, datum, varianta, odkaz).
B18: 6. Kontrola publikace | C18: V Přehledu přepněte měsíc – sloupce Publikováno a Plnění ukážou, zda skutečně zveřejněný obsah odpovídá mixu. Sekce 7 ukazuje historii po měsících.
B19: SÉRIE
C20: Novou sérii založte v listu Série (ID např. S03, název, kategorie, garant, plánovaný počet dílů). Každý díl vložte do listu Scénáře jako samostatné video s ID série a číslem dílu. Díl má vlastní kategorii, typ zpracování i měsíc publikace – do měsíčního mixu se počítá každý díl zvlášť podle svého měsíce. Pokud se změní počet dílů, upravte „Plánovaný počet dílů“ a vyplňte důvod změny.
B21: BAREVNÁ SIGNALIZACE
B22: Červená | C22: Chybí scénáře, prošlý termín, nevyřešená kontrola, poměr mimo toleranci.
B23: Žlutá / oranžová | C23: Čeká na další krok (vedení nebo marketér), chybějící údaj.
B24: Zelená | C24: Schváleno / publikováno / splněno.
B25: GOOGLE TABULKY
C26: Soubor nahrajte na Disk Google, otevřete a zvolte Soubor → Uložit jako Tabulky Google. Vzorce, rozbalovací seznamy i barevné zvýraznění fungují beze změn, získáte historii verzí a souběžnou práci více lidí. Pracujte dál jen v googlovské verzi.
B27: ZÁSADY
C28: Nemažte a nepřejmenovávejte stavy v Nastavení (používají je vzorce). Neměňte pořadí sloupců v listu Scénáře. Nové řádky vkládejte do volných řádků pod poslední záznam (vzorce jsou připravené do řádku 503; u sérií do 103). Ukázkové řádky označené „UKÁZKA“ smažte, až začnete pracovat naostro.

Sheet Přehled
A1: GTA PARTNERS – PŘEHLED PLÁNOVÁNÍ A KONTROLY VIDEOOBSAHU
A2: Měňte pouze dvě žluté buňky (měsíc a natáčecí cyklus). Vše ostatní se počítá automaticky z listů Scénáře, Publikace, Série a Nastavení.
A3: Vyhodnocovaný měsíc publikace | C3: 2026-11 | E3: Cíl videí za měsíc | G3: =Nastavení!$B$3 -> 16
A4: Natáčecí cyklus | C4: 2026-11 | E4: Datum natáčení | G4: =IFERROR(IF(VLOOKUP($C$4,Nastavení!$A$30:$G$53,2,FALSE())=0,"",VLOOKUP($C$4,Nastavení!$A$30:$G$53,2,FALSE())),"") -> 46346 | I4: Dní do natáčení | K4: =IF($G$4="","– (doplňte datum v Nastavení)",$G$4-TODAY()) -> 25
A5: Dnes | C5: =TODAY() -> 46321 | E5: Termín schválení scénářů | G5: =IFERROR(IF(VLOOKUP($C$4,Nastavení!$A$30:$G$53,3,FALSE())=0,"",VLOOKUP($C$4,Nastavení!$A$30:$G$53,3,FALSE())),"") -> 46339 | I5: Dní do termínu schválení | K5: =IF($G$5="","–",$G$5-TODAY()) -> 18
E6: Plán videí pro cyklus | G6: =IFERROR(IF(VLOOKUP($C$4,Nastavení!$A$30:$G$53,4,FALSE())=0,Nastavení!$B$3,VLOOKUP($C$4,Nastavení!$A$30:$G$53,4,FALSE())),Nastavení!$B$3) -> 16 | I6: Cíl klipů z natáčecího dne | K6: =IFERROR(VLOOKUP($C$4,Nastavení!$A$30:$G$53,6,FALSE()),"30–40") -> 30–40
A8: ="1. TEMATICKÝ MIX – plánovaný měsíc publikace "&$C$3&" (Plán = kolik videí má vyjít; Publikováno = skutečně zveřejněno v tomto měsíci)" -> 1. TEMATICKÝ MIX – plánovaný měsíc publikace 2026-11 (Plán = kolik videí má vyjít; Publikováno = skutečně zveřejněno v tomto měsíci)
A9: Kategorie | B9: Cíl % | C9: Plán (ks) | D9: Navrženo (scénáře) | E9: Schváleno | F9: Chybí ke schválení | G9: Natočeno | H9: Publikováno | I9: Plnění publikace | J9: Stav
A10: =Nastavení!$A$10 -> Nábor, vedení lidí a práce s týmem | B10: =Nastavení!$B$10 -> 0.3 | C10: =Nastavení!$E$10 -> 5 | D10: =COUNTIFS(Scénáře!$F$4:$F$503,$C$3,Scénáře!$G$4:$G$503,$A10,Scénáře!$W$4:$W$503,"<>Zrušeno",Scénáře!$W$4:$W$503,"<>Odloženo") -> 2 | E10: =COUNTIFS(Scénáře!$F$4:$F$503,$C$3,Scénáře!$G$4:$G$503,$A10,Scénáře!$W$4:$W$503,"Schváleno") -> 1 | F10: =MAX(0,C10-E10) -> 4 | G10: =SUMPRODUCT((Scénáře!$F$4:$F$503=$C$3)*(Scénáře!$G$4:$G$503=$A10)*((Scénáře!$AA$4:$AA$503="Natočeno")+(Scénáře!$AA$4:$AA$503="Ve střihu")+(Scénáře!$AA$4:$AA$503="Sestříháno")+(Scénáře!$AA$4:$AA$503="Publikováno"))) -> 1 | H10: =COUNTIFS(Scénáře!$AH$4:$AH$503,$C$3,Scénáře!$G$4:$G$503,$A10) -> 0 | I10: =IF(C10=0,"",H10/C10) -> 0 | J10: =IF(C10=0,"–",IF(H10>=C10,"Publikováno ✔",IF(E10>=C10,"Schváleno ✔",IF(D10>=C10,"Čeká na schválení","CHYBÍ SCÉNÁŘE")))) -> CHYBÍ SCÉNÁŘE
A11: =Nastavení!$A$11 -> Osobní brand & Lifestyle | B11: =Nastavení!$B$11 -> 0.4 | C11: =Nastavení!$E$11 -> 6 | D11: =COUNTIFS(Scénáře!$F$4:$F$503,$C$3,Scénáře!$G$4:$G$503,$A11,Scénáře!$W$4:$W$503,"<>Zrušeno",Scénáře!$W$4:$W$503,"<>Odloženo") -> 2 | E11: =COUNTIFS(Scénáře!$F$4:$F$503,$C$3,Scénáře!$G$4:$G$503,$A11,Scénáře!$W$4:$W$503,"Schváleno") -> 1 | F11: =MAX(0,C11-E11) -> 5 | G11: =SUMPRODUCT((Scénáře!$F$4:$F$503=$C$3)*(Scénáře!$G$4:$G$503=$A11)*((Scénáře!$AA$4:$AA$503="Natočeno")+(Scénáře!$AA$4:$AA$503="Ve střihu")+(Scénáře!$AA$4:$AA$503="Sestříháno")+(Scénáře!$AA$4:$AA$503="Publikováno"))) -> 0 | H11: =COUNTIFS(Scénáře!$AH$4:$AH$503,$C$3,Scénáře!$G$4:$G$503,$A11) -> 0 | I11: =IF(C11=0,"",H11/C11) -> 0 | J11: =IF(C11=0,"–",IF(H11>=C11,"Publikováno ✔",IF(E11>=C11,"Schváleno ✔",IF(D11>=C11,"Čeká na schválení","CHYBÍ SCÉNÁŘE")))) -> CHYBÍ SCÉNÁŘE
A12: =Nastavení!$A$12 -> Trendy a reakce na trh | B12: =Nastavení!$B$12 -> 0.2 | C12: =Nastavení!$E$12 -> 3 | D12: =COUNTIFS(Scénáře!$F$4:$F$503,$C$3,Scénáře!$G$4:$G$503,$A12,Scénáře!$W$4:$W$503,"<>Zrušeno",Scénáře!$W$4:$W$503,"<>Odloženo") -> 1 | E12: =COUNTIFS(Scénáře!$F$4:$F$503,$C$3,Scénáře!$G$4:$G$503,$A12,Scénáře!$W$4:$W$503,"Schváleno") -> 0 | F12: =MAX(0,C12-E12) -> 3 | G12: =SUMPRODUCT((Scénáře!$F$4:$F$503=$C$3)*(Scénáře!$G$4:$G$503=$A12)*((Scénáře!$AA$4:$AA$503="Natočeno")+(Scénáře!$AA$4:$AA$503="Ve střihu")+(Scénáře!$AA$4:$AA$503="Sestříháno")+(Scénáře!$AA$4:$AA$503="Publikováno"))) -> 0 | H12: =COUNTIFS(Scénáře!$AH$4:$AH$503,$C$3,Scénáře!$G$4:$G$503,$A12) -> 0 | I12: =IF(C12=0,"",H12/C12) -> 0 | J12: =IF(C12=0,"–",IF(H12>=C12,"Publikováno ✔",IF(E12>=C12,"Schváleno ✔",IF(D12>=C12,"Čeká na schválení","CHYBÍ SCÉNÁŘE")))) -> CHYBÍ SCÉNÁŘE
A13: =Nastavení!$A$13 -> Produktové a poradenské tipy | B13: =Nastavení!$B$13 -> 0.1 | C13: =Nastavení!$E$13 -> 2 | D13: =COUNTIFS(Scénáře!$F$4:$F$503,$C$3,Scénáře!$G$4:$G$503,$A13,Scénáře!$W$4:$W$503,"<>Zrušeno",Scénáře!$W$4:$W$503,"<>Odloženo") -> 2 | E13: =COUNTIFS(Scénáře!$F$4:$F$503,$C$3,Scénáře!$G$4:$G$503,$A13,Scénáře!$W$4:$W$503,"Schváleno") -> 1 | F13: =MAX(0,C13-E13) -> 1 | G13: =SUMPRODUCT((Scénáře!$F$4:$F$503=$C$3)*(Scénáře!$G$4:$G$503=$A13)*((Scénáře!$AA$4:$AA$503="Natočeno")+(Scénáře!$AA$4:$AA$503="Ve střihu")+(Scénáře!$AA$4:$AA$503="Sestříháno")+(Scénáře!$AA$4:$AA$503="Publikováno"))) -> 0 | H13: =COUNTIFS(Scénáře!$AH$4:$AH$503,$C$3,Scénáře!$G$4:$G$503,$A13) -> 0 | I13: =IF(C13=0,"",H13/C13) -> 0 | J13: =IF(C13=0,"–",IF(H13>=C13,"Publikováno ✔",IF(E13>=C13,"Schváleno ✔",IF(D13>=C13,"Čeká na schválení","CHYBÍ SCÉNÁŘE")))) -> Čeká na schválení
A14: Celkem | B14: =SUM(B10:B13) -> 1 | C14: =SUM(C10:C13) -> 16 | D14: =SUM(D10:D13) -> 7 | E14: =SUM(E10:E13) -> 3 | F14: =SUM(F10:F13) -> 13 | G14: =SUM(G10:G13) -> 1 | H14: =SUM(H10:H13) -> 0 | I14: =IF(C14=0,"",H14/C14) -> 0 | J14: =IF(C14=0,"–",IF(H14>=C14,"Publikováno ✔",IF(E14>=C14,"Schváleno ✔",IF(D14>=C14,"Čeká na schválení","CHYBÍ SCÉNÁŘE")))) -> CHYBÍ SCÉNÁŘE
A16: ="2. ODBORNĚ HODNOTNÁ vs. INSTAGRAMOVÁ VIDEA – měsíc "&$C$3 -> 2. ODBORNĚ HODNOTNÁ vs. INSTAGRAMOVÁ VIDEA – měsíc 2026-11
A17: Typ zpracování | B17: Cíl % | C17: Plán (ks) | D17: Navrženo (scénáře) | E17: Schváleno | F17: Chybí ke schválení | G17: Natočeno | H17: Publikováno | I17: Plnění publikace | J17: Stav
A18: =Nastavení!$A$18 -> Odborně hodnotné | B18: =Nastavení!$B$18 -> 0.3 | C18: =Nastavení!$E$18 -> 5 | D18: =COUNTIFS(Scénáře!$F$4:$F$503,$C$3,Scénáře!$H$4:$H$503,$A18,Scénáře!$W$4:$W$503,"<>Zrušeno",Scénáře!$W$4:$W$503,"<>Odloženo") -> 2 | E18: =COUNTIFS(Scénáře!$F$4:$F$503,$C$3,Scénáře!$H$4:$H$503,$A18,Scénáře!$W$4:$W$503,"Schváleno") -> 1 | F18: =MAX(0,C18-E18) -> 4 | G18: =SUMPRODUCT((Scénáře!$F$4:$F$503=$C$3)*(Scénáře!$H$4:$H$503=$A18)*((Scénáře!$AA$4:$AA$503="Natočeno")+(Scénáře!$AA$4:$AA$503="Ve střihu")+(Scénáře!$AA$4:$AA$503="Sestříháno")+(Scénáře!$AA$4:$AA$503="Publikováno"))) -> 0 | H18: =COUNTIFS(Scénáře!$AH$4:$AH$503,$C$3,Scénáře!$H$4:$H$503,$A18) -> 0 | I18: =IF(C18=0,"",H18/C18) -> 0 | J18: =IF(C18=0,"–",IF(H18>=C18,"Publikováno ✔",IF(E18>=C18,"Schváleno ✔",IF(D18>=C18,"Čeká na schválení","CHYBÍ SCÉNÁŘE")))) -> CHYBÍ SCÉNÁŘE
A19: =Nastavení!$A$19 -> Instagramové | B19: =Nastavení!$B$19 -> 0.7 | C19: =Nastavení!$E$19 -> 11 | D19: =COUNTIFS(Scénáře!$F$4:$F$503,$C$3,Scénáře!$H$4:$H$503,$A19,Scénáře!$W$4:$W$503,"<>Zrušeno",Scénáře!$W$4:$W$503,"<>Odloženo") -> 5 | E19: =COUNTIFS(Scénáře!$F$4:$F$503,$C$3,Scénáře!$H$4:$H$503,$A19,Scénáře!$W$4:$W$503,"Schváleno") -> 2 | F19: =MAX(0,C19-E19) -> 9 | G19: =SUMPRODUCT((Scénáře!$F$4:$F$503=$C$3)*(Scénáře!$H$4:$H$503=$A19)*((Scénáře!$AA$4:$AA$503="Natočeno")+(Scénáře!$AA$4:$AA$503="Ve střihu")+(Scénáře!$AA$4:$AA$503="Sestříháno")+(Scénáře!$AA$4:$AA$503="Publikováno"))) -> 1 | H19: =COUNTIFS(Scénáře!$AH$4:$AH$503,$C$3,Scénáře!$H$4:$H$503,$A19) -> 0 | I19: =IF(C19=0,"",H19/C19) -> 0 | J19: =IF(C19=0,"–",IF(H19>=C19,"Publikováno ✔",IF(E19>=C19,"Schváleno ✔",IF(D19>=C19,"Čeká na schválení","CHYBÍ SCÉNÁŘE")))) -> CHYBÍ SCÉNÁŘE
A20: Celkem | B20: =SUM(B18:B19) -> 1 | C20: =SUM(C18:C19) -> 16 | D20: =SUM(D18:D19) -> 7 | E20: =SUM(E18:E19) -> 3 | F20: =SUM(F18:F19) -> 13 | G20: =SUM(G18:G19) -> 1 | H20: =SUM(H18:H19) -> 0 | I20: =IF(C20=0,"",H20/C20) -> 0 | J20: =IF(C20=0,"–",IF(H20>=C20,"Publikováno ✔",IF(E20>=C20,"Schváleno ✔",IF(D20>=C20,"Čeká na schválení","CHYBÍ SCÉNÁŘE")))) -> CHYBÍ SCÉNÁŘE
A22: ="3. CHARAKTER OSOBNÍCH PROFILŮ (osobní 70 % / pracovní 30 %) – měsíc "&$C$3&" (tolerance ±"&Nastavení!$B$5&" p. b.)" -> 3. CHARAKTER OSOBNÍCH PROFILŮ (osobní 70 % / pracovní 30 %) – měsíc 2026-11 (tolerance ±10 p. b.)
A23: Profil | B23: Charakter | C23: Cíl % | D23: Scénáře (ks) | E23: Scénáře % | F23: Stav přípravy | G23: Publikováno (ks) | H23: Publikováno % | I23: Stav publikace
A24: Honza | B24: Osobní | C24: =Nastavení!$B$24 -> 0.7 | D24: =COUNTIFS(Scénáře!$F$4:$F$503,$C$3,Scénáře!$I$4:$I$503,$A24,Scénáře!$J$4:$J$503,$B24,Scénáře!$W$4:$W$503,"<>Zrušeno",Scénáře!$W$4:$W$503,"<>Odloženo") -> 1 | E24: =IF(D24+D25=0,"",D24/(D24+D25)) -> 0.5 | F24: =IF(E24="","– (žádné scénáře)",IF(ABS(E24-C24)<=Nastavení!$B$5/100,"OK","MIMO POMĚR")) -> MIMO POMĚR | G24: =COUNTIFS(Scénáře!$AH$4:$AH$503,$C$3,Scénáře!$I$4:$I$503,$A24,Scénáře!$J$4:$J$503,$B24) -> 0 | H24: =IF(G24+G25=0,"",G24/(G24+G25)) | I24: =IF(H24="","– (nic nepublikováno)",IF(ABS(H24-C24)<=Nastavení!$B$5/100,"OK","MIMO POMĚR")) -> – (nic nepublikováno)
A25: Honza | B25: Pracovní | C25: =Nastavení!$B$25 -> 0.3 | D25: =COUNTIFS(Scénáře!$F$4:$F$503,$C$3,Scénáře!$I$4:$I$503,$A25,Scénáře!$J$4:$J$503,$B25,Scénáře!$W$4:$W$503,"<>Zrušeno",Scénáře!$W$4:$W$503,"<>Odloženo") -> 1 | E25: =IF(D24+D25=0,"",D25/(D24+D25)) -> 0.5 | F25: =IF(E25="","– (žádné scénáře)",IF(ABS(E25-C25)<=Nastavení!$B$5/100,"OK","MIMO POMĚR")) -> MIMO POMĚR | G25: =COUNTIFS(Scénáře!$AH$4:$AH$503,$C$3,Scénáře!$I$4:$I$503,$A25,Scénáře!$J$4:$J$503,$B25) -> 0 | H25: =IF(G24+G25=0,"",G25/(G24+G25)) | I25: =IF(H25="","– (nic nepublikováno)",IF(ABS(H25-C25)<=Nastavení!$B$5/100,"OK","MIMO POMĚR")) -> – (nic nepublikováno)
A26: Radek | B26: Osobní | C26: =Nastavení!$B$24 -> 0.7 | D26: =COUNTIFS(Scénáře!$F$4:$F$503,$C$3,Scénáře!$I$4:$I$503,$A26,Scénáře!$J$4:$J$503,$B26,Scénáře!$W$4:$W$503,"<>Zrušeno",Scénáře!$W$4:$W$503,"<>Odloženo") -> 1 | E26: =IF(D26+D27=0,"",D26/(D26+D27)) -> 0.25 | F26: =IF(E26="","– (žádné scénáře)",IF(ABS(E26-C26)<=Nastavení!$B$5/100,"OK","MIMO POMĚR")) -> MIMO POMĚR | G26: =COUNTIFS(Scénáře!$AH$4:$AH$503,$C$3,Scénáře!$I$4:$I$503,$A26,Scénáře!$J$4:$J$503,$B26) -> 0 | H26: =IF(G26+G27=0,"",G26/(G26+G27)) | I26: =IF(H26="","– (nic nepublikováno)",IF(ABS(H26-C26)<=Nastavení!$B$5/100,"OK","MIMO POMĚR")) -> – (nic nepublikováno)
A27: Radek | B27: Pracovní | C27: =Nastavení!$B$25 -> 0.3 | D27: =COUNTIFS(Scénáře!$F$4:$F$503,$C$3,Scénáře!$I$4:$I$503,$A27,Scénáře!$J$4:$J$503,$B27,Scénáře!$W$4:$W$503,"<>Zrušeno",Scénáře!$W$4:$W$503,"<>Odloženo") -> 3 | E27: =IF(D26+D27=0,"",D27/(D26+D27)) -> 0.75 | F27: =IF(E27="","– (žádné scénáře)",IF(ABS(E27-C27)<=Nastavení!$B$5/100,"OK","MIMO POMĚR")) -> MIMO POMĚR | G27: =COUNTIFS(Scénáře!$AH$4:$AH$503,$C$3,Scénáře!$I$4:$I$503,$A27,Scénáře!$J$4:$J$503,$B27) -> 0 | H27: =IF(G26+G27=0,"",G27/(G26+G27)) | I27: =IF(H27="","– (nic nepublikováno)",IF(ABS(H27-C27)<=Nastavení!$B$5/100,"OK","MIMO POMĚR")) -> – (nic nepublikováno)
A29: ="4. STAV SCÉNÁŘŮ A SCHVALOVÁNÍ – natáčecí cyklus "&$C$4&" (kdo má udělat další krok)" -> 4. STAV SCÉNÁŘŮ A SCHVALOVÁNÍ – natáčecí cyklus 2026-11 (kdo má udělat další krok)
A30: Ukazatel | B30: Vybraný cyklus | C30: Všechny cykly | D30: Poznámka
A31: Plán videí pro cyklus | B31: =$G$6 -> 16 | D31: Z listu Nastavení (tabulka cyklů).
A32: Scénářů celkem (bez odložených a zrušených) | B32: =COUNTIFS(Scénáře!$E$4:$E$503,$C$4,Scénáře!$W$4:$W$503,"<>Zrušeno",Scénáře!$W$4:$W$503,"<>Odloženo") -> 7 | C32: =COUNTIFS(Scénáře!$A$4:$A$503,"<>",Scénáře!$W$4:$W$503,"<>Zrušeno",Scénáře!$W$4:$W$503,"<>Odloženo") -> 10 | D32: Vše, co marketéři vložili.
A33: Čeká na zpětnou vazbu vedení (K připomínkám + K finálnímu schválení) | B33: =COUNTIFS(Scénáře!$E$4:$E$503,$C$4,Scénáře!$W$4:$W$503,"K připomínkám")+COUNTIFS(Scénáře!$E$4:$E$503,$C$4,Scénáře!$W$4:$W$503,"K finálnímu schválení") -> 2 | C33: =COUNTIFS(Scénáře!$W$4:$W$503,"K připomínkám")+COUNTIFS(Scénáře!$W$4:$W$503,"K finálnímu schválení") -> 2 | D33: Další krok: Honza / Radek.
A34: Čeká na marketéry (Rozpracováno + K dopracování) | B34: =COUNTIFS(Scénáře!$E$4:$E$503,$C$4,Scénáře!$W$4:$W$503,"Rozpracováno")+COUNTIFS(Scénáře!$E$4:$E$503,$C$4,Scénáře!$W$4:$W$503,"K dopracování") -> 2 | C34: =COUNTIFS(Scénáře!$W$4:$W$503,"Rozpracováno")+COUNTIFS(Scénáře!$W$4:$W$503,"K dopracování") -> 3 | D34: Další krok: marketing.
A35: Schváleno | B35: =COUNTIFS(Scénáře!$E$4:$E$503,$C$4,Scénáře!$W$4:$W$503,"Schváleno") -> 3 | C35: =COUNTIFS(Scénáře!$W$4:$W$503,"Schváleno") -> 5
A36: Chybí schválených do plánu cyklu | B36: =MAX(0,B31-B35) -> 13 | D36: Plán − schváleno.
A37: Schváleno a čeká na natáčení | B37: =COUNTIFS(Scénáře!$E$4:$E$503,$C$4,Scénáře!$W$4:$W$503,"Schváleno",Scénáře!$AA$4:$AA$503,"Čeká na natáčení")+COUNTIFS(Scénáře!$E$4:$E$503,$C$4,Scénáře!$W$4:$W$503,"Schváleno",Scénáře!$AA$4:$AA$503,"") -> 2 | C37: =COUNTIFS(Scénáře!$W$4:$W$503,"Schváleno",Scénáře!$AA$4:$AA$503,"Čeká na natáčení")+COUNTIFS(Scénáře!$W$4:$W$503,"Schváleno",Scénáře!$AA$4:$AA$503,"") -> 2 | D37: Před natáčením vyfiltrujte v listu Scénáře: Stav schválení = Schváleno.
A38: Po termínu odevzdání scénáře (neschválené) | B38: =SUMPRODUCT((Scénáře!$E$4:$E$503=$C$4)*(Scénáře!$U$4:$U$503<>"")*(Scénáře!$U$4:$U$503<TODAY())*(Scénáře!$W$4:$W$503<>"Schváleno")*(Scénáře!$W$4:$W$503<>"Odloženo")*(Scénáře!$W$4:$W$503<>"Zrušeno")) -> 1 | C38: =SUMPRODUCT((Scénáře!$U$4:$U$503<>"")*(Scénáře!$U$4:$U$503<TODAY())*(Scénáře!$W$4:$W$503<>"Schváleno")*(Scénáře!$W$4:$W$503<>"Odloženo")*(Scénáře!$W$4:$W$503<>"Zrušeno")) -> 1 | D38: Termín odevzdání scénáře už prošel.
A39: Neschváleno po termínu schválení cyklu | B39: =COUNTIFS(Scénáře!$E$4:$E$503,$C$4,Scénáře!$AI$4:$AI$503,"*Neschváleno po termínu cyklu*") -> 0 | C39: =COUNTIF(Scénáře!$AI$4:$AI$503,"*Neschváleno po termínu cyklu*") -> 0 | D39: Termín schválení (datum natáčení − 7 dní) prošel a scénář není schválen.
A40: Otevřené připomínky (Nevyřešeno) | B40: =SUMIFS(Scénáře!$AE$4:$AE$503,Scénáře!$E$4:$E$503,$C$4) -> 2 | C40: =SUM(Scénáře!$AE$4:$AE$503) -> 2 | D40: Z listu Připomínky.
A41: Natočeno (vč. ve střihu a publikovaných) | B41: =SUMPRODUCT((Scénáře!$E$4:$E$503=$C$4)*((Scénáře!$AA$4:$AA$503="Natočeno")+(Scénáře!$AA$4:$AA$503="Ve střihu")+(Scénáře!$AA$4:$AA$503="Sestříháno")+(Scénáře!$AA$4:$AA$503="Publikováno"))) -> 1 | C41: =SUMPRODUCT(((Scénáře!$AA$4:$AA$503="Natočeno")+(Scénáře!$AA$4:$AA$503="Ve střihu")+(Scénáře!$AA$4:$AA$503="Sestříháno")+(Scénáře!$AA$4:$AA$503="Publikováno"))) -> 3
A42: Odloženo / Zrušeno | B42: =COUNTIFS(Scénáře!$E$4:$E$503,$C$4,Scénáře!$W$4:$W$503,"Odloženo")+COUNTIFS(Scénáře!$E$4:$E$503,$C$4,Scénáře!$W$4:$W$503,"Zrušeno") -> 0 | C42: =COUNTIFS(Scénáře!$W$4:$W$503,"Odloženo")+COUNTIFS(Scénáře!$W$4:$W$503,"Zrušeno") -> 0
A44: ="5. TEMATICKÝ MIX PRO NATÁČECÍ CYKLUS "&$C$4&" (plán "&$G$6&" videí – fáze plánování a schvalování)" -> 5. TEMATICKÝ MIX PRO NATÁČECÍ CYKLUS 2026-11 (plán 16 videí – fáze plánování a schvalování)
A45: Kategorie | B45: Cíl % | C45: Plán (ks) | D45: Navrženo (scénáře) | E45: Schváleno | F45: Chybí ke schválení | G45: Natočeno | H45: Stav
...

Sheet Scénáře
A1: DATABÁZE TÉMAT A SCÉNÁŘŮ – jeden řádek = jedno unikátní video nebo jeden díl série
A2: VYPLŇUJE MARKETÉR | W2: VYPLŇUJE VEDENÍ (Honza / Radek) | AA2: VÝROBA A POSTPRODUKCE | AE2: AUTOMATICKY – NEPŘEPISOVAT
A3: ID videa | B3: Pracovní název | C3: ID série | D3: Číslo dílu | E3: Natáčecí cyklus | F3: Plánovaný měsíc publikace | G3: Tematická kategorie | H3: Typ zpracování | I3: Primární profil | J3: Charakter pro osobní profil | K3: Typ obsahu | L3: Původní ID videa (při novém zpracování / střihu) | M3: Cíl videa | N3: Hlavní myšlenka | O3: Kompletní scénář (text nebo odkaz na dokument) | P3: Hook A | Q3: Hook B | R3: Hook C | S3: Produkční požadavky (lokace, rekvizity, účinkující) | T3: Zodpovědný marketér | U3: Termín odevzdání scénáře | V3: Poznámky marketéra | W3: Stav schválení | X3: Schválil | Y3: Datum schválení | Z3: Poznámka vedení | AA3: Stav výroby | AB3: Skutečné datum natáčení | AC3: Odkaz na natočený materiál | AD3: Odkaz na finální video | AE3: Otevřené připomínky | AF3: Počet publikací | AG3: Datum první publikace | AH3: Skutečný měsíc publikace | AI3: Kontrola (co je potřeba dořešit)
A4: V001 | B4: UKÁZKA – Proč jsme vzali asistentku bez praxe | E4: 2026-10 | F4: 2026-10 | G4: Nábor, vedení lidí a práce s týmem | H4: Odborně hodnotné | I4: GTA Partners | J4: Nevztahuje se | K4: Nové téma | M4: Ukázat firemní kulturu a mentoring. | N4: U nás roste každý, kdo chce. | O4: https://docs.google.com/… (odkaz na scénář) | P4: Vzali jsme člověka bez praxe. Tady je proč. | Q4: Praxe se dá naučit. Postoj ne. | S4: Kancelář, Honza + asistentka | T4: Marketér A | U4: 46300 | W4: Schváleno | X4: Honza | Y4: 46302 | AA4: Publikováno | AB4: 46305 | AD4: https://… finální video | AE4: =IF($A4="","",COUNTIFS(Připomínky!$A$4:$A$503,$A4,Připomínky!$J$4:$J$503,"Nevyřešeno")) -> 0 | AF4: =IF($A4="","",COUNTIFS(Publikace!$A$4:$A$503,$A4)) -> 2 | AG4: =IF($A4="","",IF(AF4=0,"",_xlfn.MINIFS(Publikace!$E$4:$E$503,Publikace!$A$4:$A$503,$A4))) -> 46305 | AH4: =IF(AG4="","",YEAR(AG4)&"-"&TEXT(MONTH(AG4),"00")) -> 2026-10 | AI4: =IF($A4="","",TRIM(IF(AND($U4<>"",$U4<TODAY(),$W4<>"Schváleno",$W4<>"Odloženo",$W4<>"Zrušeno"),"Po termínu odevzdání. ","")&IF(AND($W4="Schváleno",OR($X4="",$Y4="")),"Schváleno bez jména / data. ","")&IF(OR($G4="",$H4="",$I4="",$F4=""),"Chybí zařazení (kategorie, typ, profil nebo měsíc). ","")&IF(AND(OR($I4="Honza",$I4="Radek"),OR($J4="",$J4="Nevztahuje se")),"Doplnit charakter (osobní / pracovní). ","")&IF(AND($W4="Schváleno",$AE4>0),"Schváleno, ale má otevřené připomínky. ","")&IF(AND($AA4="Publikováno",$AF4=0),"Publikováno bez záznamu v listu Publikace. ","")&IF(AND($C4<>"",$D4=""),"Chybí číslo dílu série. ","")&IF(AND($E4<>"",$W4<>"Schváleno",$W4<>"Odloženo",$W4<>"Zrušeno",IFERROR(VLOOKUP($E4,Nastavení!$A$30:$G$53,3,FALSE()),0)>0,IFERROR(VLOOKUP($E4,Nastavení!$A$30:$G$53,3,FALSE()),0)<TODAY()),"Neschváleno po termínu cyklu. ","")))
A5: V002 | B5: UKÁZKA – Ranní rutina před schůzkou s klientem | E5: 2026-10 | F5: 2026-10 | G5: Osobní brand & Lifestyle | H5: Instagramové | I5: Honza | J5: Osobní | K5: Nové téma | M5: Zákulisí, lidskost. | N5: Disciplína začíná ráno. | O5: Text scénáře… | P5: 5:45. Takhle vypadá moje ráno. | S5: Domov, exteriér | T5: Marketér B | U5: 46300 | W5: Schváleno | X5: Radek | Y5: 46302 | AA5: Publikováno | AB5: 46305 | AE5: =IF($A5="","",COUNTIFS(Připomínky!$A$4:$A$503,$A5,Připomínky!$J$4:$J$503,"Nevyřešeno")) -> 0 | AF5: =IF($A5="","",COUNTIFS(Publikace!$A$4:$A$503,$A5)) -> 1 | AG5: =IF($A5="","",IF(AF5=0,"",_xlfn.MINIFS(Publikace!$E$4:$E$503,Publikace!$A$4:$A$503,$A5))) -> 46305 | AH5: =IF(AG5="","",YEAR(AG5)&"-"&TEXT(MONTH(AG5),"00")) -> 2026-10 | AI5: =IF($A5="","",TRIM(IF(AND($U5<>"",$U5<TODAY(),$W5<>"Schváleno",$W5<>"Odloženo",$W5<>"Zrušeno"),"Po termínu odevzdání. ","")&IF(AND($W5="Schváleno",OR($X5="",$Y5="")),"Schváleno bez jména / data. ","")&IF(OR($G5="",$H5="",$I5="",$F5=""),"Chybí zařazení (kategorie, typ, profil nebo měsíc). ","")&IF(AND(OR($I5="Honza",$I5="Radek"),OR($J5="",$J5="Nevztahuje se")),"Doplnit charakter (osobní / pracovní). ","")&IF(AND($W5="Schváleno",$AE5>0),"Schváleno, ale má otevřené připomínky. ","")&IF(AND($AA5="Publikováno",$AF5=0),"Publikováno bez záznamu v listu Publikace. ","")&IF(AND($C5<>"",$D5=""),"Chybí číslo dílu série. ","")&IF(AND($E5<>"",$W5<>"Schváleno",$W5<>"Odloženo",$W5<>"Zrušeno",IFERROR(VLOOKUP($E5,Nastavení!$A$30:$G$53,3,FALSE()),0)>0,IFERROR(VLOOKUP($E5,Nastavení!$A$30:$G$53,3,FALSE()),0)<TODAY()),"Neschváleno po termínu cyklu. ","")))
A6: V003 | B6: UKÁZKA – Co udělá ČNB se sazbami a co to znamená pro hypotéky | E6: 2026-11 | F6: 2026-11 | G6: Trendy a reakce na trh | H6: Odborně hodnotné | I6: Radek | J6: Pracovní | K6: Nové téma | M6: Reakce na aktuální rozhodnutí ČNB. | N6: Sazby klesají pomaleji, než se čeká – jak to využít. | O6: Text scénáře… | P6: ČNB právě rozhodla. Tohle to znamená pro vaši hypotéku. | Q6: Čekáte s hypotékou na nižší sazby? Chyba. | S6: Kancelář, grafika sazeb | T6: Marketér A | U6: 46329 | W6: K připomínkám | AA6: Čeká na natáčení | AE6: =IF($A6="","",COUNTIFS(Připomínky!$A$4:$A$503,$A6,Připomínky!$J$4:$J$503,"Nevyřešeno")) -> 1 | AF6: =IF($A6="","",COUNTIFS(Publikace!$A$4:$A$503,$A6)) -> 0 | AG6: =IF($A6="","",IF(AF6=0,"",_xlfn.MINIFS(Publikace!$E$4:$E$503,Publikace!$A$4:$A$503,$A6))) | AH6: =IF(AG6="","",YEAR(AG6)&"-"&TEXT(MONTH(AG6),"00")) | AI6: =IF($A6="","",TRIM(IF(AND($U6<>"",$U6<TODAY(),$W6<>"Schváleno",$W6<>"Odloženo",$W6<>"Zrušeno"),"Po termínu odevzdání. ","")&IF(AND($W6="Schváleno",OR($X6="",$Y6="")),"Schváleno bez jména / data. ","")&IF(OR($G6="",$H6="",$I6="",$F6=""),"Chybí zařazení (kategorie, typ, profil nebo měsíc). ","")&IF(AND(OR($I6="Honza",$I6="Radek"),OR($J6="",$J6="Nevztahuje se")),"Doplnit charakter (osobní / pracovní). ","")&IF(AND($W6="Schváleno",$AE6>0),"Schváleno, ale má otevřené připomínky. ","")&IF(AND($AA6="Publikováno",$AF6=0),"Publikováno bez záznamu v listu Publikace. ","")&IF(AND($C6<>"",$D6=""),"Chybí číslo dílu série. ","")&IF(AND($E6<>"",$W6<>"Schváleno",$W6<>"Odloženo",$W6<>"Zrušeno",IFERROR(VLOOKUP($E6,Nastavení!$A$30:$G$53,3,FALSE()),0)>0,IFERROR(VLOOKUP($E6,Nastavení!$A$30:$G$53,3,FALSE()),0)<TODAY()),"Neschváleno po termínu cyklu. ","")))
A7: V004 | B7: UKÁZKA – Investiční chyby: díl 1 – Čekání na správný okamžik | C7: S01 | D7: 1 | E7: 2026-11 | F7: 2026-11 | G7: Produktové a poradenské tipy | H7: Odborně hodnotné | I7: Radek | J7: Pracovní | K7: Nové téma | M7: Otevřít sérii, vysvětlit princip pravidelného investování. | N7: Čas na trhu > časování trhu. | O7: Text scénáře… | P7: Nejčastější chyba investorů? Čekání. | S7: Kancelář | T7: Marketér A | U7: 46329 | W7: Schváleno | X7: Radek | Y7: 46331 | AA7: Čeká na natáčení | AE7: =IF($A7="","",COUNTIFS(Připomínky!$A$4:$A$503,$A7,Připomínky!$J$4:$J$503,"Nevyřešeno")) -> 0 | AF7: =IF($A7="","",COUNTIFS(Publikace!$A$4:$A$503,$A7)) -> 0 | AG7: =IF($A7="","",IF(AF7=0,"",_xlfn.MINIFS(Publikace!$E$4:$E$503,Publikace!$A$4:$A$503,$A7))) | AH7: =IF(AG7="","",YEAR(AG7)&"-"&TEXT(MONTH(AG7),"00")) | AI7: =IF($A7="","",TRIM(IF(AND($U7<>"",$U7<TODAY(),$W7<>"Schváleno",$W7<>"Odloženo",$W7<>"Zrušeno"),"Po termínu odevzdání. ","")&IF(AND($W7="Schváleno",OR($X7="",$Y7="")),"Schváleno bez jména / data. ","")&IF(OR($G7="",$H7="",$I7="",$F7=""),"Chybí zařazení (kategorie, typ, profil nebo měsíc). ","")&IF(AND(OR($I7="Honza",$I7="Radek"),OR($J7="",$J7="Nevztahuje se")),"Doplnit charakter (osobní / pracovní). ","")&IF(AND($W7="Schváleno",$AE7>0),"Schváleno, ale má otevřené připomínky. ","")&IF(AND($AA7="Publikováno",$AF7=0),"Publikováno bez záznamu v listu Publikace. ","")&IF(AND($C7<>"",$D7=""),"Chybí číslo dílu série. ","")&IF(AND($E7<>"",$W7<>"Schváleno",$W7<>"Odloženo",$W7<>"Zrušeno",IFERROR(VLOOKUP($E7,Nastavení!$A$30:$G$53,3,FALSE()),0)>0,IFERROR(VLOOKUP($E7,Nastavení!$A$30:$G$53,3,FALSE()),0)<TODAY()),"Neschváleno po termínu cyklu. ","")))
A8: V005 | B8: UKÁZKA – Investiční chyby: díl 2 – Všechno do jedné akcie | C8: S01 | D8: 2 | E8: 2026-11 | F8: 2026-11 | G8: Produktové a poradenské tipy | H8: Instagramové | I8: Radek | J8: Pracovní | K8: Nové téma | M8: Diverzifikace s humorem. | N8: Nedávej všechna vejce do jednoho košíku. | O8: Text scénáře… | P8: Koupil jsem jednu akcii. Pak přišlo tohle. | S8: Kancelář, rekvizita košík s vejci | T8: Marketér A | U8: 46329 | W8: K dopracování | Z8: Zkrátit, doplnit konkrétní čísla. | AA8: Čeká na natáčení | AE8: =IF($A8="","",COUNTIFS(Připomínky!$A$4:$A$503,$A8,Připomínky!$J$4:$J$503,"Nevyřešeno")) -> 0 | AF8: =IF($A8="","",COUNTIFS(Publikace!$A$4:$A$503,$A8)) -> 0 | AG8: =IF($A8="","",IF(AF8=0,"",_xlfn.MINIFS(Publikace!$E$4:$E$503,Publikace!$A$4:$A$503,$A8))) | AH8: =IF(AG8="","",YEAR(AG8)&"-"&TEXT(MONTH(AG8),"00")) | AI8: =IF($A8="","",TRIM(IF(AND($U8<>"",$U8<TODAY(),$W8<>"Schváleno",$W8<>"Odloženo",$W8<>"Zrušeno"),"Po termínu odevzdání. ","")&IF(AND($W8="Schváleno",OR($X8="",$Y8="")),"Schváleno bez jména / data. ","")&IF(OR($G8="",$H8="",$I8="",$F8=""),"Chybí zařazení (kategorie, typ, profil nebo měsíc). ","")&IF(AND(OR($I8="Honza",$I8="Radek"),OR($J8="",$J8="Nevztahuje se")),"Doplnit charakter (osobní / pracovní). ","")&IF(AND($W8="Schváleno",$AE8>0),"Schváleno, ale má otevřené připomínky. ","")&IF(AND($AA8="Publikováno",$AF8=0),"Publikováno bez záznamu v listu Publikace. ","")&IF(AND($C8<>"",$D8=""),"Chybí číslo dílu série. ","")&IF(AND($E8<>"",$W8<>"Schváleno",$W8<>"Odloženo",$W8<>"Zrušeno",IFERROR(VLOOKUP($E8,Nastavení!$A$30:$G$53,3,FALSE()),0)>0,IFERROR(VLOOKUP($E8,Nastavení!$A$30:$G$53,3,FALSE()),0)<TODAY()),"Neschváleno po termínu cyklu. ","")))
A9: V006 | B9: UKÁZKA – Investiční chyby: díl 3 – Panický prodej | C9: S01 | D9: 3 | E9: 2026-12 | F9: 2026-12 | G9: Produktové a poradenské tipy | H9: Odborně hodnotné | I9: Radek | J9: Pracovní | K9: Nové téma | M9: Vysvětlit chování při poklesu trhu. | N9: Pokles není ztráta, dokud neprodáš. | O9: Text scénáře… | P9: Trh spadl o 20 %. Co teď? | S9: Kancelář | T9: Marketér A | U9: 46351 | W9: Rozpracováno | AE9: =IF($A9="","",COUNTIFS(Připomínky!$A$4:$A$503,$A9,Připomínky!$J$4:$J$503,"Nevyřešeno")) -> 0 | AF9: =IF($A9="","",COUNTIFS(Publikace!$A$4:$A$503,$A9)) -> 0 | AG9: =IF($A9="","",IF(AF9=0,"",_xlfn.MINIFS(Publikace!$E$4:$E$503,Publikace!$A$4:$A$503,$A9))) | AH9: =IF(AG9="","",YEAR(AG9)&"-"&TEXT(MONTH(AG9),"00")) | AI9: =IF($A9="","",TRIM(IF(AND($U9<>"",$U9<TODAY(),$W9<>"Schváleno",$W9<>"Odloženo",$W9<>"Zrušeno"),"Po termínu odevzdání. ","")&IF(AND($W9="Schváleno",OR($X9="",$Y9="")),"Schváleno bez jména / data. ","")&IF(OR($G9="",$H9="",$I9="",$F9=""),"Chybí zařazení (kategorie, typ, profil nebo měsíc). ","")&IF(AND(OR($I9="Honza",$I9="Radek"),OR($J9="",$J9="Nevztahuje se")),"Doplnit charakter (osobní / pracovní). ","")&IF(AND($W9="Schváleno",$AE9>0),"Schváleno, ale má otevřené připomínky. ","")&IF(AND($AA9="Publikováno",$AF9=0),"Publikováno bez záznamu v listu Publikace. ","")&IF(AND($C9<>"",$D9=""),"Chybí číslo dílu série. ","")&IF(AND($E9<>"",$W9<>"Schváleno",$W9<>"Odloženo",$W9<>"Zrušeno",IFERROR(VLOOKUP($E9,Nastavení!$A$30:$G$53,3,FALSE()),0)>0,IFERROR(VLOOKUP($E9,Nastavení!$A$30:$G$53,3,FALSE()),0)<TODAY()),"Neschváleno po termínu cyklu. ","")))
A10: V007 | B10: UKÁZKA – Víkend s rodinou na horách | E10: 2026-11 | F10: 2026-11 | G10: Osobní brand & Lifestyle | H10: Instagramové | I10: Radek | J10: Osobní | K10: Nové téma | M10: Osobní stránka profilu. | N10: Práce není všechno. | O10: Text scénáře… | P10: Vypnul jsem telefon na 48 hodin. | S10: Exteriér, hory | T10: Marketér B | U10: 46315 | W10: K dopracování | Z10: Chybí pointa, dopracovat závěr. | AA10: Čeká na natáčení | AE10: =IF($A10="","",COUNTIFS(Připomínky!$A$4:$A$503,$A10,Připomínky!$J$4:$J$503,"Nevyřešeno")) -> 1 | AF10: =IF($A10="","",COUNTIFS(Publikace!$A$4:$A$503,$A10)) -> 0 | AG10: =IF($A10="","",IF(AF10=0,"",_xlfn.MINIFS(Publikace!$E$4:$E$503,Publikace!$A$4:$A$503,$A10))) | AH10: =IF(AG10="","",YEAR(AG10)&"-"&TEXT(MONTH(AG10),"00")) | AI10: =IF($A10="","",TRIM(IF(AND($U10<>"",$U10<TODAY(),$W10<>"Schváleno",$W10<>"Odloženo",$W10<>"Zrušeno"),"Po termínu odevzdání. ","")&IF(AND($W10="Schváleno",OR($X10="",$Y10="")),"Schváleno bez jména / data. ","")&IF(OR($G10="",$H10="",$I10="",$F10=""),"Chybí zařazení (kategorie, typ, profil nebo měsíc). ","")&IF(AND(OR($I10="Honza",$I10="Radek"),OR($J10="",$J10="Nevztahuje se")),"Doplnit charakter (osobní / pracovní). ","")&IF(AND($W10="Schváleno",$AE10>0),"Schváleno, ale má otevřené připomínky. ","")&IF(AND($AA10="Publikováno",$AF10=0),"Publikováno bez záznamu v listu Publikace. ","")&IF(AND($C10<>"",$D10=""),"Chybí číslo dílu série. ","")&IF(AND($E10<>"",$W10<>"Schváleno",$W10<>"Odloženo",$W10<>"Zrušeno",IFERROR(VLOOKUP($E10,Nastavení!$A$30:$G$53,3,FALSE()),0)>0,IFERROR(VLOOKUP($E10,Nastavení!$A$30:$G$53,3,FALSE()),0)<TODAY()),"Neschváleno po termínu cyklu. ",""))) -> Po termínu odevzdání.
A11: V008 | B11: UKÁZKA – Jak u nás vypadá první měsíc nováčka | E11: 2026-11 | F11: 2026-11 | G11: Nábor, vedení lidí a práce s týmem | H11: Instagramové | I11: GTA Partners | J11: Nevztahuje se | K11: Nové téma | M11: Nábor – ukázat onboarding. | N11: Nikdo u nás není sám. | O11: Text scénáře… | P11: První den. První klient. První výplata. | S11: Kancelář, 2–3 kolegové | T11: Marketér B | U11: 46329 | W11: K finálnímu schválení | AA11: Čeká na natáčení | AE11: =IF($A11="","",COUNTIFS(Připomínky!$A$4:$A$503,$A11,Připomínky!$J$4:$J$503,"Nevyřešeno")) -> 0 | AF11: =IF($A11="","",COUNTIFS(Publikace!$A$4:$A$503,$A11)) -> 0 | AG11: =IF($A11="","",IF(AF11=0,"",_xlfn.MINIFS(Publikace!$E$4:$E$503,Publikace!$A$4:$A$503,$A11))) | AH11: =IF(AG11="","",YEAR(AG11)&"-"&TEXT(MONTH(AG11),"00")) | AI11: =IF($A11="","",TRIM(IF(AND($U11<>"",$U11<TODAY(),$W11<>"Schváleno",$W11<>"Odloženo",$W11<>"Zrušeno"),"Po termínu odevzdání. ","")&IF(AND($W11="Schváleno",OR($X11="",$Y11="")),"Schváleno bez jména / data. ","")&IF(OR($G11="",$H11="",$I11="",$F11=""),"Chybí zařazení (kategorie, typ, profil nebo měsíc). ","")&IF(AND(OR($I11="Honza",$I11="Radek"),OR($J11="",$J11="Nevztahuje se")),"Doplnit charakter (osobní / pracovní). ","")&IF(AND($W11="Schváleno",$AE11>0),"Schváleno, ale má otevřené připomínky. ","")&IF(AND($AA11="Publikováno",$AF11=0),"Publikováno bez záznamu v listu Publikace. ","")&IF(AND($C11<>"",$D11=""),"Chybí číslo dílu série. ","")&IF(AND($E11<>"",$W11<>"Schváleno",$W11<>"Odloženo",$W11<>"Zrušeno",IFERROR(VLOOKUP($E11,Nastavení!$A$30:$G$53,3,FALSE()),0)>0,IFERROR(VLOOKUP($E11,Nastavení!$A$30:$G$53,3,FALSE()),0)<TODAY()),"Neschváleno po termínu cyklu. ","")))
A12: V009 | B12: UKÁZKA – Běžecká výzva: týden 1 | E12: 2026-11 | F12: 2026-11 | G12: Osobní brand & Lifestyle | H12: Instagramové | I12: Honza | J12: Osobní | K12: Nové téma | M12: Osobní výzva, pravidelný obsah. | N12: Malé kroky každý den. | O12: Text scénáře… | P12: Slíbil jsem 100 km za měsíc. Den 1. | S12: Exteriér | T12: Marketér B | U12: 46329 | W12: Schváleno | X12: Honza | Y12: 46330 | AA12: Čeká na natáčení | AE12: =IF($A12="","",COUNTIFS(Připomínky!$A$4:$A$503,$A12,Připomínky!$J$4:$J$503,"Nevyřešeno")) -> 0 | AF12: =IF($A12="","",COUNTIFS(Publikace!$A$4:$A$503,$A12)) -> 0 | AG12: =IF($A12="","",IF(AF12=0,"",_xlfn.MINIFS(Publikace!$E$4:$E$503,Publikace!$A$4:$A$503,$A12))) | AH12: =IF(AG12="","",YEAR(AG12)&"-"&TEXT(MONTH(AG12),"00")) | AI12: =IF($A12="","",TRIM(IF(AND($U12<>"",$U12<TODAY(),$W12<>"Schváleno",$W12<>"Odloženo",$W12<>"Zrušeno"),"Po termínu odevzdání. ","")&IF(AND($W12="Schváleno",OR($X12="",$Y12="")),"Schváleno bez jména / data. ","")&IF(OR($G12="",$H12="",$I12="",$F12=""),"Chybí zařazení (kategorie, typ, profil nebo měsíc). ","")&IF(AND(OR($I12="Honza",$I12="Radek"),OR($J12="",$J12="Nevztahuje se")),"Doplnit charakter (osobní / pracovní). ","")&IF(AND($W12="Schváleno",$AE12>0),"Schváleno, ale má otevřené připomínky. ","")&IF(AND($AA12="Publikováno",$AF12=0),"Publikováno bez záznamu v listu Publikace. ","")&IF(AND($C12<>"",$D12=""),"Chybí číslo dílu série. ","")&IF(AND($E12<>"",$W12<>"Schváleno",$W12<>"Odloženo",$W12<>"Zrušeno",IFERROR(VLOOKUP($E12,Nastavení!$A$30:$G$53,3,FALSE()),0)>0,IFERROR(VLOOKUP($E12,Nastavení!$A$30:$G$53,3,FALSE()),0)<TODAY()),"Neschváleno po termínu cyklu. ","")))
A13: V010 | B13: UKÁZKA – Nový střih: Proč jsme vzali asistentku bez praxe | E13: 2026-11 | F13: 2026-11 | G13: Nábor, vedení lidí a práce s týmem | H13: Instagramové | I13: Honza | J13: Pracovní | K13: Nový střih existujícího videa | L13: V001 | M13: Využít úspěšné téma na osobním profilu. | N13: Postoj > praxe. | O13: Použít materiál z V001 | P13: Tohle nikdo v oboru nedělá. | S13: Bez natáčení – jen střih | T13: Marketér A | U13: 46329 | W13: Schváleno | X13: Honza | Y13: 46331 | AA13: Ve střihu | AE13: =IF($A13="","",COUNTIFS(Připomínky!$A$4:$A$503,$A13,Připomínky!$J$4:$J$503,"Nevyřešeno")) -> 0 | AF13: =IF($A13="","",COUNTIFS(Publikace!$A$4:$A$503,$A13)) -> 0 | AG13: =IF($A13="","",IF(AF13=0,"",_xlfn.MINIFS(Publikace!$E$4:$E$503,Publikace!$A$4:$A$503,$A13))) | AH13: =IF(AG13="","",YEAR(AG13)&"-"&TEXT(MONTH(AG13),"00")) | AI13: =IF($A13="","",TRIM(IF(AND($U13<>"",$U13<TODAY(),$W13<>"Schváleno",$W13<>"Odloženo",$W13<>"Zrušeno"),"Po termínu odevzdání. ","")&IF(AND($W13="Schváleno",OR($X13="",$Y13="")),"Schváleno bez jména / data. ","")&IF(OR($G13="",$H13="",$I13="",$F13=""),"Chybí zařazení (kategorie, typ, profil nebo měsíc). ","")&IF(AND(OR($I13="Honza",$I13="Radek"),OR($J13="",$J13="Nevztahuje se")),"Doplnit charakter (osobní / pracovní). ","")&IF(AND($W13="Schváleno",$AE13>0),"Schváleno, ale má otevřené připomínky. ","")&IF(AND($AA13="Publikováno",$AF13=0),"Publikováno bez záznamu v listu Publikace. ","")&IF(AND($C13<>"",$D13=""),"Chybí číslo dílu série. ","")&IF(AND($E13<>"",$W13<>"Schváleno",$W13<>"Odloženo",$W13<>"Zrušeno",IFERROR(VLOOKUP($E13,Nastavení!$A$30:$G$53,3,FALSE()),0)>0,IFERROR(VLOOKUP($E13,Nastavení!$A$30:$G$53,3,FALSE()),0)<TODAY()),"Neschváleno po termínu cyklu. ","")))
AE14: =IF($A14="","",COUNTIFS(Připomínky!$A$4:$A$503,$A14,Připomínky!$J$4:$J$503,"Nevyřešeno")) | AF14: =IF($A14="","",COUNTIFS(Publikace!$A$4:$A$503,$A14)) | AG14: =IF($A14="","",IF(AF14=0,"",_xlfn.MINIFS(Publikace!$E$4:$E$503,Publikace!$A$4:$A$503,$A14))) | AH14: =IF(AG14="","",YEAR(AG14)&"-"&TEXT(MONTH(AG14),"00")) | AI14: =IF($A14="","",TRIM(IF(AND($U14<>"",$U14<TODAY(),$W14<>"Schváleno",$W14<>"Odloženo",$W14<>"Zrušeno"),"Po termínu odevzdání. ","")&IF(AND($W14="Schváleno",OR($X14="",$Y14="")),"Schváleno bez jména / data. ","")&IF(OR($G14="",$H14="",$I14="",$F14=""),"Chybí zařazení (kategorie, typ, profil nebo měsíc). ","")&IF(AND(OR($I14="Honza",$I14="Radek"),OR($J14="",$J14="Nevztahuje se")),"Doplnit charakter (osobní / pracovní). ","")&IF(AND($W14="Schváleno",$AE14>0),"Schváleno, ale má otevřené připomínky. ","")&IF(AND($AA14="Publikováno",$AF14=0),"Publikováno bez záznamu v listu Publikace. ","")&IF(AND($C14<>"",$D14=""),"Chybí číslo dílu série. ","")&IF(AND($E14<>"",$W14<>"Schváleno",$W14<>"Odloženo",$W14<>"Zrušeno",IFERROR(VLOOKUP($E14,Nastavení!$A$30:$G$53,3,FALSE()),0)>0,IFERROR(VLOOKUP($E14,Nastavení!$A$30:$G$53,3,FALSE()),0)<TODAY()),"Neschváleno po termínu cyklu. ","")))
AE15: =IF($A15="","",COUNTIFS(Připomínky!$A$4:$A$503,$A15,Připomínky!$J$4:$J$503,"Nevyřešeno")) | AF15: =IF($A15="","",COUNTIFS(Publikace!$A$4:$A$503,$A15)) | AG15: =IF($A15="","",IF(AF15=0,"",_xlfn.MINIFS(Publikace!$E$4:$E$503,Publikace!$A$4:$A$503,$A15))) | AH15: =IF(AG15="","",YEAR(AG15)&"-"&TEXT(MONTH(AG15),"00")) | AI15: =IF($A15="","",TRIM(IF(AND($U15<>"",$U15<TODAY(),$W15<>"Schváleno",$W15<>"Odloženo",$W15<>"Zrušeno"),"Po termínu odevzdání. ","")&IF(AND($W15="Schváleno",OR($X15="",$Y15="")),"Schváleno bez jména / data. ","")&IF(OR($G15="",$H15="",$I15="",$F15=""),"Chybí zařazení (kategorie, typ, profil nebo měsíc). ","")&IF(AND(OR($I15="Honza",$I15="Radek"),OR($J15="",$J15="Nevztahuje se")),"Doplnit charakter (osobní / pracovní). ","")&IF(AND($W15="Schváleno",$AE15>0),"Schváleno, ale má otevřené připomínky. ","")&IF(AND($AA15="Publikováno",$AF15=0),"Publikováno bez záznamu v listu Publikace. ","")&IF(AND($C15<>"",$D15=""),"Chybí číslo dílu série. ","")&IF(AND($E15<>"",$W15<>"Schváleno",$W15<>"Odloženo",$W15<>"Zrušeno",IFERROR(VLOOKUP($E15,Nastavení!$A$30:$G$53,3,FALSE()),0)>0,IFERROR(VLOOKUP($E15,Nastavení!$A$30:$G$53,3,FALSE()),0)<TODAY()),"Neschváleno po termínu cyklu. ","")))
AE16: =IF($A16="","",COUNTIFS(Připomínky!$A$4:$A$503,$A16,Připomínky!$J$4:$J$503,"Nevyřešeno")) | AF16: =IF($A16="","",COUNTIFS(Publikace!$A$4:$A$503,$A16)) | AG16: =IF($A16="","",IF(AF16=0,"",_xlfn.MINIFS(Publikace!$E$4:$E$503,Publikace!$A$4:$A$503,$A16))) | AH16: =IF(AG16="","",YEAR(AG16)&"-"&TEXT(MONTH(AG16),"00")) | AI16: =IF($A16="","",TRIM(IF(AND($U16<>"",$U16<TODAY(),$W16<>"Schváleno",$W16<>"Odloženo",$W16<>"Zrušeno"),"Po termínu odevzdání. ","")&IF(AND($W16="Schváleno",OR($X16="",$Y16="")),"Schváleno bez jména / data. ","")&IF(OR($G16="",$H16="",$I16="",$F16=""),"Chybí zařazení (kategorie, typ, profil nebo měsíc). ","")&IF(AND(OR($I16="Honza",$I16="Radek"),OR($J16="",$J16="Nevztahuje se")),"Doplnit charakter (osobní / pracovní). ","")&IF(AND($W16="Schváleno",$AE16>0),"Schváleno, ale má otevřené připomínky. ","")&IF(AND($AA16="Publikováno",$AF16=0),"Publikováno bez záznamu v listu Publikace. ","")&IF(AND($C16<>"",$D16=""),"Chybí číslo dílu série. ","")&IF(AND($E16<>"",$W16<>"Schváleno",$W16<>"Odloženo",$W16<>"Zrušeno",IFERROR(VLOOKUP($E16,Nastavení!$A$30:$G$53,3,FALSE()),0)>0,IFERROR(VLOOKUP($E16,Nastavení!$A$30:$G$53,3,FALSE()),0)<TODAY()),"Neschváleno po termínu cyklu. ","")))
AE17: =IF($A17="","",COUNTIFS(Připomínky!$A$4:$A$503,$A17,Připomínky!$J$4:$J$503,"Nevyřešeno")) | AF17: =IF($A17="","",COUNTIFS(Publikace!$A$4:$A$503,$A17)) | AG17: =IF($A17="","",IF(AF17=0,"",_xlfn.MINIFS(Publikace!$E$4:$E$503,Publikace!$A$4:$A$503,$A17))) | AH17: =IF(AG17="","",YEAR(AG17)&"-"&TEXT(MONTH(AG17),"00")) | AI17: =IF($A17="","",TRIM(IF(AND($U17<>"",$U17<TODAY(),$W17<>"Schváleno",$W17<>"Odloženo",$W17<>"Zrušeno"),"Po termínu odevzdání. ","")&IF(AND($W17="Schváleno",OR($X17="",$Y17="")),"Schváleno bez jména / data. ","")&IF(OR($G17="",$H17="",$I17="",$F17=""),"Chybí zařazení (kategorie, typ, profil nebo měsíc). ","")&IF(AND(OR($I17="Honza",$I17="Radek"),OR($J17="",$J17="Nevztahuje se")),"Doplnit charakter (osobní / pracovní). ","")&IF(AND($W17="Schváleno",$AE17>0),"Schváleno, ale má otevřené připomínky. ","")&IF(AND($AA17="Publikováno",$AF17=0),"Publikováno bez záznamu v listu Publikace. ","")&IF(AND($C17<>"",$D17=""),"Chybí číslo dílu série. ","")&IF(AND($E17<>"",$W17<>"Schváleno",$W17<>"Odloženo",$W17<>"Zrušeno",IFERROR(VLOOKUP($E17,Nastavení!$A$30:$G$53,3,FALSE()),0)>0,IFERROR(VLOOKUP($E17,Nastavení!$A$30:$G$53,3,FALSE()),0)<TODAY()),"Neschváleno po termínu cyklu. ","")))
AE18: =IF($A18="","",COUNTIFS(Připomínky!$A$4:$A$503,$A18,Připomínky!$J$4:$J$503,"Nevyřešeno")) | AF18: =IF($A18="","",COUNTIFS(Publikace!$A$4:$A$503,$A18)) | AG18: =IF($A18="","",IF(AF18=0,"",_xlfn.MINIFS(Publikace!$E$4:$E$503,Publikace!$A$4:$A$503,$A18))) | AH18: =IF(AG18="","",YEAR(AG18)&"-"&TEXT(MONTH(AG18),"00")) | AI18: =IF($A18="","",TRIM(IF(AND($U18<>"",$U18<TODAY(),$W18<>"Schváleno",$W18<>"Odloženo",$W18<>"Zrušeno"),"Po termínu odevzdání. ","")&IF(AND($W18="Schváleno",OR($X18="",$Y18="")),"Schváleno bez jména / data. ","")&IF(OR($G18="",$H18="",$I18="",$F18=""),"Chybí zařazení (kategorie, typ, profil nebo měsíc). ","")&IF(AND(OR($I18="Honza",$I18="Radek"),OR($J18="",$J18="Nevztahuje se")),"Doplnit charakter (osobní / pracovní). ","")&IF(AND($W18="Schváleno",$AE18>0),"Schváleno, ale má otevřené připomínky. ","")&IF(AND($AA18="Publikováno",$AF18=0),"Publikováno bez záznamu v listu Publikace. ","")&IF(AND($C18<>"",$D18=""),"Chybí číslo dílu série. ","")&IF(AND($E18<>"",$W18<>"Schváleno",$W18<>"Odloženo",$W18<>"Zrušeno",IFERROR(VLOOKUP($E18,Nastavení!$A$30:$G$53,3,FALSE()),0)>0,IFERROR(VLOOKUP($E18,Nastavení!$A$30:$G$53,3,FALSE()),0)<TODAY()),"Neschváleno po termínu cyklu. ","")))
AE19: =IF($A19="","",COUNTIFS(Připomínky!$A$4:$A$503,$A19,Připomínky!$J$4:$J$503,"Nevyřešeno")) | AF19: =IF($A19="","",COUNTIFS(Publikace!$A$4:$A$503,$A19)) | AG19: =IF($A19="","",IF(AF19=0,"",_xlfn.MINIFS(Publikace!$E$4:$E$503,Publikace!$A$4:$A$503,$A19))) | AH19: =IF(AG19="","",YEAR(AG19)&"-"&TEXT(MONTH(AG19),"00")) | AI19: =IF($A19="","",TRIM(IF(AND($U19<>"",$U19<TODAY(),$W19<>"Schváleno",$W19<>"Odloženo",$W19<>"Zrušeno"),"Po termínu odevzdání. ","")&IF(AND($W19="Schváleno",OR($X19="",$Y19="")),"Schváleno bez jména / data. ","")&IF(OR($G19="",$H19="",$I19="",$F19=""),"Chybí zařazení (kategorie, typ, profil nebo měsíc). ","")&IF(AND(OR($I19="Honza",$I19="Radek"),OR($J19="",$J19="Nevztahuje se")),"Doplnit charakter (osobní / pracovní). ","")&IF(AND($W19="Schváleno",$AE19>0),"Schváleno, ale má otevřené připomínky. ","")&IF(AND($AA19="Publikováno",$AF19=0),"Publikováno bez záznamu v listu Publikace. ","")&IF(AND($C19<>"",$D19=""),"Chybí číslo dílu série. ","")&IF(AND($E19<>"",$W19<>"Schváleno",$W19<>"Odloženo",$W19<>"Zrušeno",IFERROR(VLOOKUP($E19,Nastavení!$A$30:$G$53,3,FALSE()),0)>0,IFERROR(VLOOKUP($E19,Nastavení!$A$30:$G$53,3,FALSE()),0)<TODAY()),"Neschváleno po termínu cyklu. ","")))
AE20: =IF($A20="","",COUNTIFS(Připomínky!$A$4:$A$503,$A20,Připomínky!$J$4:$J$503,"Nevyřešeno")) | AF20: =IF($A20="","",COUNTIFS(Publikace!$A$4:$A$503,$A20)) | AG20: =IF($A20="","",IF(AF20=0,"",_xlfn.MINIFS(Publikace!$E$4:$E$503,Publikace!$A$4:$A$503,$A20))) | AH20: =IF(AG20="","",YEAR(AG20)&"-"&TEXT(MONTH(AG20),"00")) | AI20: =IF($A20="","",TRIM(IF(AND($U20<>"",$U20<TODAY(),$W20<>"Schváleno",$W20<>"Odloženo",$W20<>"Zrušeno"),"Po termínu odevzdání. ","")&IF(AND($W20="Schváleno",OR($X20="",$Y20="")),"Schváleno bez jména / data. ","")&IF(OR($G20="",$H20="",$I20="",$F20=""),"Chybí zařazení (kategorie, typ, profil nebo měsíc). ","")&IF(AND(OR($I20="Honza",$I20="Radek"),OR($J20="",$J20="Nevztahuje se")),"Doplnit charakter (osobní / pracovní). ","")&IF(AND($W20="Schváleno",$AE20>0),"Schváleno, ale má otevřené připomínky. ","")&IF(AND($AA20="Publikováno",$AF20=0),"Publikováno bez záznamu v listu Publikace. ","")&IF(AND($C20<>"",$D20=""),"Chybí číslo dílu série. ","")&IF(AND($E20<>"",$W20<>"Schváleno",$W20<>"Odloženo",$W20<>"Zrušeno",IFERROR(VLOOKUP($E20,Nastavení!$A$30:$G$53,3,FALSE()),0)>0,IFERROR(VLOOKUP($E20,Nastavení!$A$30:$G$53,3,FALSE()),0)<TODAY()),"Neschváleno po termínu cyklu. ","")))
AE21: =IF($A21="","",COUNTIFS(Připomínky!$A$4:$A$503,$A21,Připomínky!$J$4:$J$503,"Nevyřešeno")) | AF21: =IF($A21="","",COUNTIFS(Publikace!$A$4:$A$503,$A21)) | AG21: =IF($A21="","",IF(AF21=0,"",_xlfn.MINIFS(Publikace!$E$4:$E$503,Publikace!$A$4:$A$503,$A21))) | AH21: =IF(AG21="","",YEAR(AG21)&"-"&TEXT(MONTH(AG21),"00")) | AI21: =IF($A21="","",TRIM(IF(AND($U21<>"",$U21<TODAY(),$W21<>"Schváleno",$W21<>"Odloženo",$W21<>"Zrušeno"),"Po termínu odevzdání. ","")&IF(AND($W21="Schváleno",OR($X21="",$Y21="")),"Schváleno bez jména / data. ","")&IF(OR($G21="",$H21="",$I21="",$F21=""),"Chybí zařazení (kategorie, typ, profil nebo měsíc). ","")&IF(AND(OR($I21="Honza",$I21="Radek"),OR($J21="",$J21="Nevztahuje se")),"Doplnit charakter (osobní / pracovní). ","")&IF(AND($W21="Schváleno",$AE21>0),"Schváleno, ale má otevřené připomínky. ","")&IF(AND($AA21="Publikováno",$AF21=0),"Publikováno bez záznamu v listu Publikace. ","")&IF(AND($C21<>"",$D21=""),"Chybí číslo dílu série. ","")&IF(AND($E21<>"",$W21<>"Schváleno",$W21<>"Odloženo",$W21<>"Zrušeno",IFERROR(VLOOKUP($E21,Nastavení!$A$30:$G$53,3,FALSE()),0)>0,IFERROR(VLOOKUP($E21,Nastavení!$A$30:$G$53,3,FALSE()),0)<TODAY()),"Neschváleno po termínu cyklu. ","")))
AE22: =IF($A22="","",COUNTIFS(Připomínky!$A$4:$A$503,$A22,Připomínky!$J$4:$J$503,"Nevyřešeno")) | AF22: =IF($A22="","",COUNTIFS(Publikace!$A$4:$A$503,$A22)) | AG22: =IF($A22="","",IF(AF22=0,"",_xlfn.MINIFS(Publikace!$E$4:$E$503,Publikace!$A$4:$A$503,$A22))) | AH22: =IF(AG22="","",YEAR(AG22)&"-"&TEXT(MONTH(AG22),"00")) | AI22: =IF($A22="","",TRIM(IF(AND($U22<>"",$U22<TODAY(),$W22<>"Schváleno",$W22<>"Odloženo",$W22<>"Zrušeno"),"Po termínu odevzdání. ","")&IF(AND($W22="Schváleno",OR($X22="",$Y22="")),"Schváleno bez jména / data. ","")&IF(OR($G22="",$H22="",$I22="",$F22=""),"Chybí zařazení (kategorie, typ, profil nebo měsíc). ","")&IF(AND(OR($I22="Honza",$I22="Radek"),OR($J22="",$J22="Nevztahuje se")),"Doplnit charakter (osobní / pracovní). ","")&IF(AND($W22="Schváleno",$AE22>0),"Schváleno, ale má otevřené připomínky. ","")&IF(AND($AA22="Publikováno",$AF22=0),"Publikováno bez záznamu v listu Publikace. ","")&IF(AND($C22<>"",$D22=""),"Chybí číslo dílu série. ","")&IF(AND($E22<>"",$W22<>"Schváleno",$W22<>"Odloženo",$W22<>"Zrušeno",IFERROR(VLOOKUP($E22,Nastavení!$A$30:$G$53,3,FALSE()),0)>0,IFERROR(VLOOKUP($E22,Nastavení!$A$30:$G$53,3,FALSE()),0)<TODAY()),"Neschváleno po termínu cyklu. ","")))
AE23: =IF($A23="","",COUNTIFS(Připomínky!$A$4:$A$503,$A23,Připomínky!$J$4:$J$503,"Nevyřešeno")) | AF23: =IF($A23="","",COUNTIFS(Publikace!$A$4:$A$503,$A23)) | AG23: =IF($A23="","",IF(AF23=0,"",_xlfn.MINIFS(Publikace!$E$4:$E$503,Publikace!$A$4:$A$503,$A23))) | AH23: =IF(AG23="","",YEAR(AG23)&"-"&TEXT(MONTH(AG23),"00")) | AI23: =IF($A23="","",TRIM(IF(AND($U23<>"",$U23<TODAY(),$W23<>"Schváleno",$W23<>"Odloženo",$W23<>"Zrušeno"),"Po termínu odevzdání. ","")&IF(AND($W23="Schváleno",OR($X23="",$Y23="")),"Schváleno bez jména / data. ","")&IF(OR($G23="",$H23="",$I23="",$F23=""),"Chybí zařazení (kategorie, typ, profil nebo měsíc). ","")&IF(AND(OR($I23="Honza",$I23="Radek"),OR($J23="",$J23="Nevztahuje se")),"Doplnit charakter (osobní / pracovní). ","")&IF(AND($W23="Schváleno",$AE23>0),"Schváleno, ale má otevřené připomínky. ","")&IF(AND($AA23="Publikováno",$AF23=0),"Publikováno bez záznamu v listu Publikace. ","")&IF(AND($C23<>"",$D23=""),"Chybí číslo dílu série. ","")&IF(AND($E23<>"",$W23<>"Schváleno",$W23<>"Odloženo",$W23<>"Zrušeno",IFERROR(VLOOKUP($E23,Nastavení!$A$30:$G$53,3,FALSE()),0)>0,IFERROR(VLOOKUP($E23,Nastavení!$A$30:$G$53,3,FALSE()),0)<TODAY()),"Neschváleno po termínu cyklu. ","")))
AE24: =IF($A24="","",COUNTIFS(Připomínky!$A$4:$A$503,$A24,Připomínky!$J$4:$J$503,"Nevyřešeno")) | AF24: =IF($A24="","",COUNTIFS(Publikace!$A$4:$A$503,$A24)) | AG24: =IF($A24="","",IF(AF24=0,"",_xlfn.MINIFS(Publikace!$E$4:$E$503,Publikace!$A$4:$A$503,$A24))) | AH24: =IF(AG24="","",YEAR(AG24)&"-"&TEXT(MONTH(AG24),"00")) | AI24: =IF($A24="","",TRIM(IF(AND($U24<>"",$U24<TODAY(),$W24<>"Schváleno",$W24<>"Odloženo",$W24<>"Zrušeno"),"Po termínu odevzdání. ","")&IF(AND($W24="Schváleno",OR($X24="",$Y24="")),"Schváleno bez jména / data. ","")&IF(OR($G24="",$H24="",$I24="",$F24=""),"Chybí zařazení (kategorie, typ, profil nebo měsíc). ","")&IF(AND(OR($I24="Honza",$I24="Radek"),OR($J24="",$J24="Nevztahuje se")),"Doplnit charakter (osobní / pracovní). ","")&IF(AND($W24="Schváleno",$AE24>0),"Schváleno, ale má otevřené připomínky. ","")&IF(AND($AA24="Publikováno",$AF24=0),"Publikováno bez záznamu v listu Publikace. ","")&IF(AND($C24<>"",$D24=""),"Chybí číslo dílu série. ","")&IF(AND($E24<>"",$W24<>"Schváleno",$W24<>"Odloženo",$W24<>"Zrušeno",IFERROR(VLOOKUP($E24,Nastavení!$A$30:$G$53,3,FALSE()),0)>0,IFERROR(VLOOKUP($E24,Nastavení!$A$30:$G$53,3,FALSE()),0)<TODAY()),"Neschváleno po termínu cyklu. ","")))
AE25: =IF($A25="","",COUNTIFS(Připomínky!$A$4:$A$503,$A25,Připomínky!$J$4:$J$503,"Nevyřešeno")) | AF25: =IF($A25="","",COUNTIFS(Publikace!$A$4:$A$503,$A25)) | AG25: =IF($A25="","",IF(AF25=0,"",_xlfn.MINIFS(Publikace!$E$4:$E$503,Publikace!$A$4:$A$503,$A25))) | AH25: =IF(AG25="","",YEAR(AG25)&"-"&TEXT(MONTH(AG25),"00")) | AI25: =IF($A25="","",TRIM(IF(AND($U25<>"",$U25<TODAY(),$W25<>"Schváleno",$W25<>"Odloženo",$W25<>"Zrušeno"),"Po termínu odevzdání. ","")&IF(AND($W25="Schváleno",OR($X25="",$Y25="")),"Schváleno bez jména / data. ","")&IF(OR($G25="",$H25="",$I25="",$F25=""),"Chybí zařazení (kategorie, typ, profil nebo měsíc). ","")&IF(AND(OR($I25="Honza",$I25="Radek"),OR($J25="",$J25="Nevztahuje se")),"Doplnit charakter (osobní / pracovní). ","")&IF(AND($W25="Schváleno",$AE25>0),"Schváleno, ale má otevřené připomínky. ","")&IF(AND($AA25="Publikováno",$AF25=0),"Publikováno bez záznamu v listu Publikace. ","")&IF(AND($C25<>"",$D25=""),"Chybí číslo dílu série. ","")&IF(AND($E25<>"",$W25<>"Schváleno",$W25<>"Odloženo",$W25<>"Zrušeno",IFERROR(VLOOKUP($E25,Nastavení!$A$30:$G$53,3,FALSE()),0)>0,IFERROR(VLOOKUP($E25,Nastavení!$A$30:$G$53,3,FALSE()),0)<TODAY()),"Neschváleno po termínu cyklu. ","")))
... AE503: =IF($A503="","",COUNTIFS(Připomínky!$A$4:$A$503,$A503,Připomínky!$J$4:$J$503,"Nevyřešeno")) | AF503: =IF($A503="","",COUNTIFS(Publikace!$A$4:$A$503,$A503)) | AG503: =IF($A503="","",IF(AF503=0,"",_xlfn.MINIFS(Publikace!$E$4:$E$503,Publikace!$A$4:$A$503,$A503))) | AH503: =IF(AG503="","",YEAR(AG503)&"-"&TEXT(MONTH(AG503),"00")) | AI503: =IF($A503="","",TRIM(IF(AND($U503<>"",$U503<TODAY(),$W503<>"Schváleno",$W503<>"Odloženo",$W503<>"Zrušeno"),"Po termínu odevzdání. ","")&IF(AND($W503="Schváleno",OR($X503="",$Y503="")),"Schváleno bez jména / data. ","")&IF(OR($G503="",$H503="",$I503="",$F503=""),"Chybí zařazení (kategorie, typ, profil nebo měsíc). ","")&IF(AND(OR($I503="Honza",$I503="Radek"),OR($J503="",$J503="Nevztahuje se")),"Doplnit charakter (osobní / pracovní). ","")&IF(AND($W503="Schváleno",$AE503>0),"Schváleno, ale má otevřené připomínky. ","")&IF(AND($AA503="Publikováno",$AF503=0),"Publikováno bez záznamu v listu Publikace. ","")&IF(AND($C503<>"",$D503=""),"Chybí číslo dílu série. ","")&IF(AND($E503<>"",$W503<>"Schváleno",$W503<>"Odloženo",$W503<>"Zrušeno",IFERROR(VLOOKUP($E503,Nastavení!$A$30:$G$53,3,FALSE()),0)>0,IFERROR(VLOOKUP($E503,Nastavení!$A$30:$G$53,3,FALSE()),0)<TODAY()),"Neschváleno po termínu cyklu. ","")))

Sheet Připomínky
A1: PŘIPOMÍNKY A SCHVALOVÁNÍ – každá zpětná vazba Honzy / Radka = jeden řádek (zůstává dohledatelná i po zapracování)
A2: VYPLŇUJE VEDENÍ | G2: VYPLŇUJE MARKETÉR (stav uzavírá vedení)
A3: ID videa | B3: Pracovní název (automaticky) | C3: Datum vložení | D3: Autor připomínky | E3: Typ | F3: Text připomínky / odborné doplnění / návrh změny | G3: Reakce marketéra | H3: Reagoval | I3: Datum reakce | J3: Stav připomínky
A4: V003 | B4: =IF(A4="","",IFERROR(VLOOKUP(A4,Scénáře!$A$4:$B$503,2,FALSE()),"ID nenalezeno")) -> UKÁZKA – Co udělá ČNB se sazbami a co to znamená pro hypotéky | C4: 46330 | D4: Radek | E4: Odborné doplnění | F4: Doplnit aktuální výši repo sazby a konkrétní dopad na splátku u hypotéky 5 mil. | J4: Nevyřešeno
A5: V005 | B5: =IF(A5="","",IFERROR(VLOOKUP(A5,Scénáře!$A$4:$B$503,2,FALSE()),"ID nenalezeno")) -> UKÁZKA – Investiční chyby: díl 2 – Všechno do jedné akcie | C5: 46330 | D5: Radek | E5: Požadavek na úpravu | F5: Zkrátit na 40 s, přidat příklad s reálnými čísly (např. propad jedné akcie o 60 %). | G5: Zkráceno, příklad doplněn – verze 2 v dokumentu. | H5: Marketér A | I5: 46332 | J5: Zapracováno
A6: V007 | B6: =IF(A6="","",IFERROR(VLOOKUP(A6,Scénáře!$A$4:$B$503,2,FALSE()),"ID nenalezeno")) -> UKÁZKA – Víkend s rodinou na horách | C6: 46317 | D6: Honza | E6: Připomínka | F6: Chybí pointa – proč to divákovi říkáme? Navázat na téma rovnováhy práce a rodiny. | J6: Nevyřešeno
A7: V001 | B7: =IF(A7="","",IFERROR(VLOOKUP(A7,Scénáře!$A$4:$B$503,2,FALSE()),"ID nenalezeno")) -> UKÁZKA – Proč jsme vzali asistentku bez praxe | C7: 46301 | D7: Honza | E7: Souhlas / schválení | F7: Bez připomínek, schvaluji. | J7: Uzavřeno
B8: =IF(A8="","",IFERROR(VLOOKUP(A8,Scénáře!$A$4:$B$503,2,FALSE()),"ID nenalezeno"))
B9: =IF(A9="","",IFERROR(VLOOKUP(A9,Scénáře!$A$4:$B$503,2,FALSE()),"ID nenalezeno"))
B10: =IF(A10="","",IFERROR(VLOOKUP(A10,Scénáře!$A$4:$B$503,2,FALSE()),"ID nenalezeno"))
B11: =IF(A11="","",IFERROR(VLOOKUP(A11,Scénáře!$A$4:$B$503,2,FALSE()),"ID nenalezeno"))
B12: =IF(A12="","",IFERROR(VLOOKUP(A12,Scénáře!$A$4:$B$503,2,FALSE()),"ID nenalezeno"))
B13: =IF(A13="","",IFERROR(VLOOKUP(A13,Scénáře!$A$4:$B$503,2,FALSE()),"ID nenalezeno"))
B14: =IF(A14="","",IFERROR(VLOOKUP(A14,Scénáře!$A$4:$B$503,2,FALSE()),"ID nenalezeno"))
B15: =IF(A15="","",IFERROR(VLOOKUP(A15,Scénáře!$A$4:$B$503,2,FALSE()),"ID nenalezeno"))
B16: =IF(A16="","",IFERROR(VLOOKUP(A16,Scénáře!$A$4:$B$503,2,FALSE()),"ID nenalezeno"))
B17: =IF(A17="","",IFERROR(VLOOKUP(A17,Scénáře!$A$4:$B$503,2,FALSE()),"ID nenalezeno"))
B18: =IF(A18="","",IFERROR(VLOOKUP(A18,Scénáře!$A$4:$B$503,2,FALSE()),"ID nenalezeno"))
B19: =IF(A19="","",IFERROR(VLOOKUP(A19,Scénáře!$A$4:$B$503,2,FALSE()),"ID nenalezeno"))
... B503: =IF(A503="","",IFERROR(VLOOKUP(A503,Scénáře!$A$4:$B$503,2,FALSE()),"ID nenalezeno"))

Sheet Publikace
A1: PUBLIKACE – jeden řádek = jedno zveřejnění (profil × varianta). Více řádků k jednomu ID videa NEZVYŠUJE počet unikátních videí.
A3: ID videa | B3: Pracovní název (automaticky) | C3: ID série (automaticky) | D3: Profil | E3: Datum publikace | F3: Varianta (hook / střih) | G3: Odkaz na publikovaný příspěvek | H3: Výsledky / poznámka (A/B test)
A4: V001 | B4: =IF(A4="","",IFERROR(VLOOKUP(A4,Scénáře!$A$4:$B$503,2,FALSE()),"ID nenalezeno")) -> UKÁZKA – Proč jsme vzali asistentku bez praxe | C4: =IF(A4="","",IFERROR(VLOOKUP(A4,Scénáře!$A$4:$C$503,3,FALSE())&"","")) | D4: GTA Partners | E4: 46305 | F4: Hlavní verze | G4: https://instagram.com/… (ukázka)
A5: V001 | B5: =IF(A5="","",IFERROR(VLOOKUP(A5,Scénáře!$A$4:$B$503,2,FALSE()),"ID nenalezeno")) -> UKÁZKA – Proč jsme vzali asistentku bez praxe | C5: =IF(A5="","",IFERROR(VLOOKUP(A5,Scénáře!$A$4:$C$503,3,FALSE())&"","")) | D5: Honza | E5: 46307 | F5: Hook B | G5: https://instagram.com/… (ukázka) | H5: Hook B měl o 30 % vyšší dokoukanost.
A6: V002 | B6: =IF(A6="","",IFERROR(VLOOKUP(A6,Scénáře!$A$4:$B$503,2,FALSE()),"ID nenalezeno")) -> UKÁZKA – Ranní rutina před schůzkou s klientem | C6: =IF(A6="","",IFERROR(VLOOKUP(A6,Scénáře!$A$4:$C$503,3,FALSE())&"","")) | D6: Honza | E6: 46305 | F6: Hlavní verze | G6: https://instagram.com/… (ukázka)
B7: =IF(A7="","",IFERROR(VLOOKUP(A7,Scénáře!$A$4:$B$503,2,FALSE()),"ID nenalezeno")) | C7: =IF(A7="","",IFERROR(VLOOKUP(A7,Scénáře!$A$4:$C$503,3,FALSE())&"",""))
B8: =IF(A8="","",IFERROR(VLOOKUP(A8,Scénáře!$A$4:$B$503,2,FALSE()),"ID nenalezeno")) | C8: =IF(A8="","",IFERROR(VLOOKUP(A8,Scénáře!$A$4:$C$503,3,FALSE())&"",""))
B9: =IF(A9="","",IFERROR(VLOOKUP(A9,Scénáře!$A$4:$B$503,2,FALSE()),"ID nenalezeno")) | C9: =IF(A9="","",IFERROR(VLOOKUP(A9,Scénáře!$A$4:$C$503,3,FALSE())&"",""))
B10: =IF(A10="","",IFERROR(VLOOKUP(A10,Scénáře!$A$4:$B$503,2,FALSE()),"ID nenalezeno")) | C10: =IF(A10="","",IFERROR(VLOOKUP(A10,Scénáře!$A$4:$C$503,3,FALSE())&"",""))
B11: =IF(A11="","",IFERROR(VLOOKUP(A11,Scénáře!$A$4:$B$503,2,FALSE()),"ID nenalezeno")) | C11: =IF(A11="","",IFERROR(VLOOKUP(A11,Scénáře!$A$4:$C$503,3,FALSE())&"",""))
B12: =IF(A12="","",IFERROR(VLOOKUP(A12,Scénáře!$A$4:$B$503,2,FALSE()),"ID nenalezeno")) | C12: =IF(A12="","",IFERROR(VLOOKUP(A12,Scénáře!$A$4:$C$503,3,FALSE())&"",""))
B13: =IF(A13="","",IFERROR(VLOOKUP(A13,Scénáře!$A$4:$B$503,2,FALSE()),"ID nenalezeno")) | C13: =IF(A13="","",IFERROR(VLOOKUP(A13,Scénáře!$A$4:$C$503,3,FALSE())&"",""))
B14: =IF(A14="","",IFERROR(VLOOKUP(A14,Scénáře!$A$4:$B$503,2,FALSE()),"ID nenalezeno")) | C14: =IF(A14="","",IFERROR(VLOOKUP(A14,Scénáře!$A$4:$C$503,3,FALSE())&"",""))
B15: =IF(A15="","",IFERROR(VLOOKUP(A15,Scénáře!$A$4:$B$503,2,FALSE()),"ID nenalezeno")) | C15: =IF(A15="","",IFERROR(VLOOKUP(A15,Scénáře!$A$4:$C$503,3,FALSE())&"",""))
B16: =IF(A16="","",IFERROR(VLOOKUP(A16,Scénáře!$A$4:$B$503,2,FALSE()),"ID nenalezeno")) | C16: =IF(A16="","",IFERROR(VLOOKUP(A16,Scénáře!$A$4:$C$503,3,FALSE())&"",""))
B17: =IF(A17="","",IFERROR(VLOOKUP(A17,Scénáře!$A$4:$B$503,2,FALSE()),"ID nenalezeno")) | C17: =IF(A17="","",IFERROR(VLOOKUP(A17,Scénáře!$A$4:$C$503,3,FALSE())&"",""))
B18: =IF(A18="","",IFERROR(VLOOKUP(A18,Scénáře!$A$4:$B$503,2,FALSE()),"ID nenalezeno")) | C18: =IF(A18="","",IFERROR(VLOOKUP(A18,Scénáře!$A$4:$C$503,3,FALSE())&"",""))
... B503: =IF(A503="","",IFERROR(VLOOKUP(A503,Scénáře!$A$4:$B$503,2,FALSE()),"ID nenalezeno")) | C503: =IF(A503="","",IFERROR(VLOOKUP(A503,Scénáře!$A$4:$C$503,3,FALSE())&"",""))

Sheet Série
A1: OBSAHOVÉ SÉRIE – jeden řádek = jedna série; díly se evidují v listu Scénáře (sloupec ID série + Číslo dílu)
A2: VYPLŇUJE MARKETÉR | M2: VYPLŇUJE VEDENÍ (Honza / Radek) | P2: AUTOMATICKY – NEPŘEPISOVAT
A3: ID série | B3: Název série | C3: Hlavní tematická kategorie | D3: Cíl série (co chceme komunikovat) | E3: Garant série | F3: Odpovědný marketér | G3: Plánovaný počet dílů (aktuální) | H3: Původně plánovaný počet dílů | I3: Důvod změny rozsahu | J3: Datum zahájení | K3: Předpokládané dokončení | L3: Poznámky | M3: Stav série | N3: Uzavření potvrdil | O3: Datum uzavření | P3: Díly se scénářem | Q3: Schválené díly | R3: Natočené díly | S3: Publikované díly | T3: Plnění publikace | U3: Zbývá dílů | V3: Otevřené připomínky | W3: Publikace bez odkazu | X3: Lze uzavřít? | Y3: Kontrola | Z3: Aktivní | AA3: Pořadí v Přehledu
